2025-05-04 14:17:42,999 ERROR:An error occurred when calling message handler
Traceback (most recent call last):
  File "pystray\_win32.py", line 412, in _dispatcher
  File "pystray\_win32.py", line 201, in _on_notify
  File "pystray\_base.py", line 110, in __call__
TypeError: 'tuple' object is not callable
2025-05-13 13:37:54,131 ERROR:run_all.py crashed
Traceback (most recent call last):
  File "run_all.py", line 75, in <module>
  File "run_all.py", line 55, in main
  File "process_logs.py", line 47, in process_all_logs
FileNotFoundError: [WinError 3] Системе не удается найти указанный путь: 'C:\\Users\\foren\\AppData\\Local\\Temp\\_MEI185882\\logs'
2025-05-13 13:38:00,114 ERROR:run_all.py crashed
Traceback (most recent call last):
  File "run_all.py", line 75, in <module>
  File "run_all.py", line 55, in main
  File "process_logs.py", line 47, in process_all_logs
FileNotFoundError: [WinError 3] Системе не удается найти указанный путь: 'C:\\Users\\foren\\AppData\\Local\\Temp\\_MEI158842\\logs'
2025-05-13 13:38:15,442 ERROR:run_all.py crashed
Traceback (most recent call last):
  File "run_all.py", line 75, in <module>
  File "run_all.py", line 55, in main
  File "process_logs.py", line 47, in process_all_logs
FileNotFoundError: [WinError 3] Системе не удается найти указанный путь: 'C:\\Users\\foren\\AppData\\Local\\Temp\\_MEI193882\\logs'
